data/test_data.txt
ORDER ADD,1000,AAPL,Buy,10,72.82
SUBSCRIBE BBO,AAPL
SUBSCRIBE VWAP,AAPL,1
ORDER ADD,1001,AAPL,Sell,100,72.85
ORDER ADD,1002,GGPL,Sell,100,72.85
ORDER ADD,1003,GGPL,Sell,100,72.85
ORDER MODIFY,1000,50,72.80
PRINT_FULL,AAPL
PRINT_FULL,GGPL
ORDER CANCEL,1000
ORDER ADD,1004,AAPL,Sell,25,72.85
ORDER ADD,1005,AAPL,Buy,25,72.82
ORDER ADD,1006,AAPL,Buy,30,72.82
ORDER ADD,1007,AAPL,Buy,30,72.80
ORDER ADD,1008,AAPL,Buy,15,72.80
ORDER ADD,1009,AAPL,Buy,25,72.80
ORDER ADD,1010,AAPL,Sell,25,72.81
ORDER ADD,1011,AAPL,Sell,10,72.81
ORDER ADD,1012,AAPL,Sell,5,72.81
ORDER ADD,1013,AAPL,Buy,25,72.81
ORDER ADD,1014,AAPL,Buy,10,72.81
ORDER ADD,1015,AAPL,Buy,5,72.81
ORDER ADD,1016,AAPL,Sell,25,72.82
ORDER ADD,1017,AAPL,Sell,30,72.82
ORDER ADD,1018,AAPL,Sell,25,72.84
ORDER ADD,1019,AAPL,Sell,30,72.84
PRINT_FULL,AAPL
PRINT,AAPL
PRINT,GGPL
ORDER ADD,1020,AMPL,Buy,12,72.86
ORDER ADD,1021,AMPL,Buy,22,72.86
UNSUBSCRIBE BBO,AAPL
SUBSCRIBE BBO,AMPL
SUBSCRIBE VWAP,AMPL,5
ORDER ADD,1022,AMPL,Buy,134,72.86
ORDER ADD,1023,AMPL,Buy,80,72.86
PRINT_FULL,AMPL
PRINT,AMPL
ORDER MODIFY,1022,50,72.84
PRINT,AMPL
ORDER CANCEL,1023
PRINT,AMPL
UNSUBSCRIBE BBO,AMPL
UNSUBSCRIBE VWAP,AMPL,5
ORDER ADD,1024,AMPL,Buy,80,72.86
UNSUBSCRIBE VWAP,AAPL,1
